<?xml version="1.0" ?>
<!-- =================================================================================== -->
<!-- |    This document was autogenerated by xacro from /home/andrea/catkin_ws/src/turtlex/turtlex_description/robots/turtlex_main.urdf.xacro | -->
<!-- |    EDITING THIS FILE BY HAND IS NOT RECOMMENDED                                 | -->
<!-- =================================================================================== -->
<!--
    - Base      : kobuki
    - Stacks    : hexagons
    - 3D sensor : asus xtion pro live
    - Arm 		: widowx
-->
<robot name="turtlex">
    <!--<xacro:macro name="stack_middle_pole" params="parent number x_loc y_loc z_loc">  
    <joint name="pole_middle_${number}_joint" type="fixed">
      <origin xyz="${x_loc} ${y_loc} ${z_loc}" rpy="0 0 0" />
      <parent link="${parent}"/>
      <child link="pole_middle_${number}_link"/>
    </joint>
    <link name="pole_middle_${number}_link">
      <visual>
        <origin xyz="0 0 0" rpy="0 ${M_PI} 0"/>
        <geometry>
          <mesh filename="package://turtlex_description/meshes/stacks/pole_middle_reexport.dae"/>
        </geometry>
      </visual>
      <collision>
        <origin xyz="0 0 0" rpy="0 0 0"/>
        <geometry>
          <cylinder length="0.0608" radius="0.006"/>
        </geometry>
      </collision>
      
<inertial>
        <mass value="0.012"/>
        <origin xyz="0 0 0"/>
        <inertia ixx="0.000003805" ixy="0.0" ixz="0.0"
                 iyy="0.000003805" iyz="0.0"
                 izz="0.000000216"/>
      </inertial>

    </link>
  </xacro:macro>-->
    <!--<xacro:macro name="stack_top_pole" params="parent number x_loc y_loc z_loc">  
    <joint name="pole_top_${number}_joint" type="fixed">
      <origin xyz="${x_loc} ${y_loc} ${z_loc}" rpy="0 0 0"/>
      <parent link="${parent}"/>
      <child link="pole_top_${number}_link"/>
    </joint>
    <link name="pole_top_${number}_link">
      <visual>
        <origin xyz=" 0 0 0" rpy="0 0 0"/>
        <geometry>
          <mesh filename="package://turtlex_description/meshes/stacks/pole_top_reexportdae.dae"/>
        </geometry>
      </visual>
      <collision>
        <origin xyz="0 0 0" rpy="0 0 0"/>
        <geometry>
          <cylinder length="0.2032" radius="0.006"/>
        </geometry>
      </collision>
      
<inertial>
        <mass value="0.060"/>
        <origin xyz="0 0 0"/>
        <inertia ixx="0.000206991" ixy="0.0" ixz="0.0"
                 iyy="0.000206991" iyz="0.0"
                 izz="0.000001080"/>
      </inertial>

    </link>
  </xacro:macro>-->
    <!--<xacro:macro name="stack_3d_sensor_pole" params="parent number x_loc y_loc z_loc">
    <joint name="pole_kinect_${number}_joint" type="fixed">
      <origin xyz="${x_loc} ${y_loc} ${z_loc}" rpy="0 0 0"/>
      <parent link="${parent}"/>
      <child link="pole_kinect_${number}_link"/>
    </joint>
    <link name="pole_kinect_${number}_link">
      <visual>
        <origin xyz="0 0 -0.01" rpy="0 0 0"/>
        <geometry>
          <mesh filename="package://turtlex_description/meshes/sensors/sensor_pole_reexport.dae" />
        </geometry>
      </visual>
      <collision>
        <origin xyz="0 0 0" rpy="0 0 0"/>
        <geometry>
          <cylinder length="0.0936" radius="0.006"/>
        </geometry>
      </collision>
      
<inertial>
        <mass value="0.020"/>
        <origin xyz="0 0 0"/>
        <inertia ixx="0.000014782" ixy="0.0" ixz="0.0"
                 iyy="0.000014782" iyz="0.0"
                 izz="0.000000360"/>
      </inertial>

    </link>
  </xacro:macro>-->
    <link name="base_footprint" />
    <!--
       Base link is set at the bottom of the base mould.
       This is done to be compatible with the way base link
       was configured for turtlebot 1. Refer to

       https://github.com/turtlebot/turtlebot/issues/40

       To put the base link at the more oft used wheel
       axis, set the z-distance from the base_footprint
       to 0.352.
      -->
    <joint name="base_joint" type="fixed">
        <origin rpy="0 0 0" xyz="0 0 0.0102" />
        <parent link="base_footprint" />
        <child link="base_link" />
    </joint>
    <link name="base_link">
        <visual>
            <geometry>
                <!-- new mesh -->
                <mesh filename="package://turtlex_description/meshes/main_body.dae" />
            </geometry>
            <origin rpy="0 0 0" xyz="0.001 0 0.05199" />
        </visual>
        <collision>
            <geometry>
                <cylinder length="0.10938" radius="0.178" />
            </geometry>
            <origin rpy="0 0 0" xyz="0.0 0 0.05949" />
        </collision>
        
<inertial>
            <!-- COM experimentally determined -->
            <origin xyz="0.01 0 0" />
            <mass value="2.4" />
            <!-- 2.4/2.6 kg for small/big battery pack -->
            <!-- Kobuki's inertia tensor is approximated by a cylinder with homogeneous mass distribution
             More details: http://en.wikipedia.org/wiki/List_of_moment_of_inertia_tensors
             m = 2.4 kg; h = 0.09 m; r = 0.175 m
             ixx = 1/12 * m * (3 * r^2 + h^2)
             iyy = 1/12 * m * (3 * r^2 + h^2)
             izz = 1/2 * m * r^2
          -->
            <inertia ixx="0.019995" ixy="0.0" ixz="0.0" iyy="0.019995" iyz="0.0" izz="0.03675" />
        </inertial>

    </link>
    <joint name="wheel_left_joint" type="continuous">
        <parent link="base_link" />
        <child link="wheel_left_link" />
        <origin rpy="-1.5707963267948966 0 0" xyz="0.00 0.115 0.0250" />
        <axis xyz="0 0 1" />
    </joint>
    <link name="wheel_left_link">
        <visual>
            <geometry>
                <mesh filename="package://turtlex_description/meshes/wheel.dae" />
            </geometry>
            <origin rpy="0 0 0" xyz="0 0 0" />
        </visual>
        <collision>
            <geometry>
                <cylinder length="0.0206" radius="0.0352" />
            </geometry>
            <origin rpy="0 0 0" xyz="0 0 0" />
        </collision>
        
<inertial>
            <mass value="0.01" />
            <origin xyz="0 0 0" />
            <inertia ixx="0.001" ixy="0.0" ixz="0.0" iyy="0.001" iyz="0.0" izz="0.001" />
        </inertial>

    </link>
    <joint name="wheel_right_joint" type="continuous">
        <parent link="base_link" />
        <child link="wheel_right_link" />
        <origin rpy="-1.5707963267948966 0 0" xyz="0.00 -0.115 0.0250" />
        <axis xyz="0 0 1" />
    </joint>
    <link name="wheel_right_link">
        <visual>
            <geometry>
                <mesh filename="package://turtlex_description/meshes/wheel.dae" />
            </geometry>
            <origin rpy="0 0 0" xyz="0 0 0" />
        </visual>
        <collision>
            <geometry>
                <cylinder length="0.0206" radius="0.0350" />
            </geometry>
            <origin rpy="0 0 0" xyz="0 0 0" />
        </collision>
        
<inertial>
            <mass value="0.01" />
            <origin xyz="0 0 0" />
            <inertia ixx="0.001" ixy="0.0" ixz="0.0" iyy="0.001" iyz="0.0" izz="0.001" />
        </inertial>

    </link>
    <joint name="caster_front_joint" type="fixed">
        <parent link="base_link" />
        <child link="caster_front_link" />
        <origin rpy="-1.5707963267948966 0 0" xyz="0.115 0.0 0.007" />
    </joint>
    <link name="caster_front_link">
        <collision>
            <geometry>
                <cylinder length="0.0176" radius="0.017" />
            </geometry>
            <origin rpy="0 0 0" xyz="0 0 0" />
        </collision>
        
<inertial>
            <mass value="0.01" />
            <origin xyz="0 0 0" />
            <inertia ixx="0.001" ixy="0.0" ixz="0.0" iyy="0.001" iyz="0.0" izz="0.001" />
        </inertial>

    </link>
    <joint name="caster_back_joint" type="fixed">
        <parent link="base_link" />
        <child link="caster_back_link" />
        <origin rpy="-1.5707963267948966 0 0" xyz="-0.135 0.0 0.009" />
    </joint>
    <link name="caster_back_link">
        <collision>
            <geometry>
                <cylinder length="0.0176" radius="0.017" />
            </geometry>
            <origin rpy="0 0 0" xyz="0 0 0" />
        </collision>
        
<inertial>
            <mass value="0.01" />
            <origin xyz="0 0 0" />
            <inertia ixx="0.001" ixy="0.0" ixz="0.0" iyy="0.001" iyz="0.0" izz="0.001" />
        </inertial>

    </link>
    <!-- Kobuki's sensors -->
    <joint name="gyro_joint" type="fixed">
        <axis xyz="0 1 0" />
        <origin rpy="0 0 0" xyz="0.056 0.062 0.0202" />
        <parent link="base_link" />
        <child link="gyro_link" />
    </joint>
    <link name="gyro_link">
        
<inertial>
            <mass value="0.001" />
            <origin rpy="0 0 0" xyz="0 0 0" />
            <inertia ixx="0.0001" ixy="0" ixz="0" iyy="0.000001" iyz="0" izz="0.0001" />
        </inertial>

    </link>
    <joint name="cliff_sensor_left_joint" type="fixed">
        <origin rpy="0 1.5707963267948966 0" xyz="0.08734 0.13601 0.0214" />
        <parent link="base_link" />
        <child link="cliff_sensor_left_link" />
    </joint>
    <link name="cliff_sensor_left_link">
        
<inertial>
            <mass value="0.0001" />
            <origin xyz="0 0 0" />
            <inertia ixx="0.0001" ixy="0.0" ixz="0.0" iyy="0.0001" iyz="0.0" izz="0.0001" />
        </inertial>

    </link>
    <joint name="cliff_sensor_right_joint" type="fixed">
        <origin rpy="0 1.5707963267948966 0" xyz="0.085 -0.13601 0.0214" />
        <parent link="base_link" />
        <child link="cliff_sensor_right_link" />
    </joint>
    <link name="cliff_sensor_right_link">
        
<inertial>
            <mass value="0.0001" />
            <origin xyz="0 0 0" />
            <inertia ixx="0.0001" ixy="0.0" ixz="0.0" iyy="0.0001" iyz="0.0" izz="0.0001" />
        </inertial>

    </link>
    <joint name="cliff_sensor_front_joint" type="fixed">
        <origin rpy="0 1.5707963267948966 0" xyz="0.156 0.00 0.0214" />
        <parent link="base_link" />
        <child link="cliff_sensor_front_link" />
    </joint>
    <link name="cliff_sensor_front_link">
        
<inertial>
            <mass value="0.0001" />
            <origin xyz="0 0 0" />
            <inertia ixx="0.0001" ixy="0.0" ixz="0.0" iyy="0.0001" iyz="0.0" izz="0.0001" />
        </inertial>

    </link>
    <joint name="laser_sensor_joint" type="fixed">
        <!--<origin xyz="0.0 0.0 0.435" rpy="0 0 0"/>-->
        <origin rpy="0 0 0" xyz="0.114 0.0 0.038" />
        <!--<parent link="base_link"/>-->
        <parent link="plate_bottom_link" />
        <child link="laser_sensor_link" />
    </joint>
    <link name="laser_sensor_link">
        
<inertial>
            <mass value="1e-5" />
            <origin rpy="0 0 0" xyz="0 0 0" />
            <inertia ixx="1e-6" ixy="0" ixz="0" iyy="1e-6" iyz="0" izz="1e-6" />
        </inertial>

        <collision>
            <origin rpy="0 0 0" xyz="0 0 0" />
            <geometry>
                <!--<box size="0.1 0.1 0.1"/>-->
                <box size="0.05 0.05 0.07" />
            </geometry>
        </collision>
        <visual>
            <origin rpy="0 0 0" xyz="0 0 0" />
            <geometry>
                <mesh filename="package://turtlex_description/meshes/sensors/hokuyo.dae" />
            </geometry>
        </visual>
    </link>
    <gazebo reference="wheel_left_link">
        <mu1>1.0</mu1>
        <mu2>1.0</mu2>
        <kp>1000000.0</kp>
        <kd>100.0</kd>
        <minDepth>0.001</minDepth>
        <maxVel>1.0</maxVel>
    </gazebo>
    <gazebo reference="wheel_right_link">
        <mu1>1.0</mu1>
        <mu2>1.0</mu2>
        <kp>1000000.0</kp>
        <kd>100.0</kd>
        <minDepth>0.001</minDepth>
        <maxVel>1.0</maxVel>
    </gazebo>
    <gazebo reference="caster_front_link">
        <mu1>0.0</mu1>
        <mu2>0.0</mu2>
        <kp>1000000.0</kp>
        <kd>100.0</kd>
        <minDepth>0.001</minDepth>
        <maxVel>1.0</maxVel>
    </gazebo>
    <gazebo reference="caster_back_link">
        <mu1>0.0</mu1>
        <mu2>0.0</mu2>
        <kp>1000000.0</kp>
        <kd>100.0</kd>
        <minDepth>0.001</minDepth>
        <maxVel>1.0</maxVel>
    </gazebo>
    <gazebo reference="base_link">
        <mu1>0.3</mu1>
        <mu2>0.3</mu2>
        <sensor name="bumpers" type="contact">
            <always_on>1</always_on>
            <update_rate>50.0</update_rate>
            <visualize>true</visualize>
            <contact>
                <collision>base_footprint_collision_base_link</collision>
            </contact>
        </sensor>
    </gazebo>
    <gazebo reference="cliff_sensor_left_link">
        <sensor name="cliff_sensor_left" type="ray">
            <always_on>true</always_on>
            <update_rate>50</update_rate>
            <visualize>true</visualize>
            <ray>
                <scan>
                    <horizontal>
                        <samples>50</samples>
                        <resolution>1.0</resolution>
                        <min_angle>-0.0436</min_angle>
                        <!-- -2.5 degree -->
                        <max_angle>0.0436</max_angle>
                        <!-- 2.5 degree -->
                    </horizontal>
                    <!--            Can't use vertical rays until this bug is resolved: -->
                    <!--            https://bitbucket.org/osrf/gazebo/issue/509/vertical-sensor-doesnt-works -->
                    <!-- 	          <vertical> -->
                    <!-- 	            <samples>50</samples> -->
                    <!-- 	            <resolution>1.0</resolution> -->
                    <!-- 	            <min_angle>-0.0436</min_angle>  -2.5 degree -->
                    <!-- 	            <max_angle>0.0436</max_angle> 2.5 degree -->
                    <!-- 	          </vertical> -->
                </scan>
                <range>
                    <min>0.01</min>
                    <max>0.15</max>
                    <resolution>1.0</resolution>
                </range>
            </ray>
        </sensor>
    </gazebo>
    <gazebo reference="cliff_sensor_right_link">
        <sensor name="cliff_sensor_right" type="ray">
            <always_on>true</always_on>
            <update_rate>50</update_rate>
            <visualize>true</visualize>
            <ray>
                <scan>
                    <horizontal>
                        <samples>50</samples>
                        <resolution>1.0</resolution>
                        <min_angle>-0.0436</min_angle>
                        <!-- -2.5 degree -->
                        <max_angle>0.0436</max_angle>
                        <!-- 2.5 degree -->
                    </horizontal>
                    <!--            Can't use vertical rays until this bug is resolved: -->
                    <!--            https://bitbucket.org/osrf/gazebo/issue/509/vertical-sensor-doesnt-works -->
                    <!-- 	          <vertical> -->
                    <!-- 	            <samples>50</samples> -->
                    <!-- 	            <resolution>1.0</resolution> -->
                    <!-- 	            <min_angle>-0.0436</min_angle>  -2.5 degree -->
                    <!-- 	            <max_angle>0.0436</max_angle> 2.5 degree -->
                    <!-- 	          </vertical> -->
                </scan>
                <range>
                    <min>0.01</min>
                    <max>0.15</max>
                    <resolution>1.0</resolution>
                </range>
            </ray>
        </sensor>
    </gazebo>
    <gazebo reference="cliff_sensor_front_link">
        <sensor name="cliff_sensor_front" type="ray">
            <always_on>true</always_on>
            <update_rate>50</update_rate>
            <visualize>true</visualize>
            <ray>
                <scan>
                    <horizontal>
                        <samples>50</samples>
                        <resolution>1.0</resolution>
                        <min_angle>-0.0436</min_angle>
                        <!-- -2.5 degree -->
                        <max_angle>0.0436</max_angle>
                        <!-- 2.5 degree -->
                    </horizontal>
                    <!-- 	          Can't use vertical rays until this bug is resolved: -->
                    <!--            https://bitbucket.org/osrf/gazebo/issue/509/vertical-sensor-doesnt-works -->
                    <!-- 	          <vertical> -->
                    <!-- 	            <samples>50</samples> -->
                    <!-- 	            <resolution>1.0</resolution> -->
                    <!-- 	            <min_angle>-0.0436</min_angle>  -2.5 degree -->
                    <!-- 	            <max_angle>0.0436</max_angle> 2.5 degree -->
                    <!-- 	          </vertical> -->
                </scan>
                <range>
                    <min>0.01</min>
                    <max>0.15</max>
                    <resolution>1.0</resolution>
                </range>
            </ray>
        </sensor>
    </gazebo>
    <gazebo reference="gyro_link">
        <sensor name="imu" type="imu">
            <always_on>true</always_on>
            <update_rate>50</update_rate>
            <visualize>false</visualize>
            <imu>
                <noise>
                    <type>gaussian</type>
                    <rate>
                        <mean>0.0</mean>
                        <stddev>1.96e-06</stddev>
                        <!-- 0.25 x 0.25 (deg/s) -->
                        <bias_mean>0.0</bias_mean>
                        <bias_stddev>0.0</bias_stddev>
                    </rate>
                    <accel>
                        <!-- not used in the plugin and real robot, hence using tutorial values -->
                        <mean>0.0</mean>
                        <stddev>1.7e-2</stddev>
                        <bias_mean>0.1</bias_mean>
                        <bias_stddev>0.001</bias_stddev>
                    </accel>
                </noise>
            </imu>
        </sensor>
    </gazebo>
    <gazebo>
        <plugin filename="libgazebo_ros_diff_drive.so" name="differential_drive_controller">
            <alwaysOn>true</alwaysOn>
            <updateRate>30</updateRate>
            <!--<updateRate>20</updateRate>-->
            <leftJoint>wheel_left_joint</leftJoint>
            <rightJoint>wheel_right_joint</rightJoint>
            <wheelSeparation>.230</wheelSeparation>
            <wheelDiameter>0.070</wheelDiameter>
            <!--<torque>1.0</torque>-->
            <wheelAcceleration>1</wheelAcceleration>
            <!--<wheelAcceleration>0</wheelAcceleration>-->
            <wheelTorque>10</wheelTorque>
            <!--<wheelTorque>5</wheelTorque>-->
            <commandTopic>cmd_vel</commandTopic>
            <odometryTopic>odom</odometryTopic>
            <odometryFrame>odom</odometryFrame>
            <odometrySource>world</odometrySource>
            <!-- "encoders" is also possible -->
            <publishWheelTF>false</publishWheelTF>
            <publishOdomTF>true</publishOdomTF>
            <publishTf>true</publishTf>
            <publishWheelJointState>true</publishWheelJointState>
            <robotBaseFrame>base_footprint</robotBaseFrame>
            <legacyMode>false</legacyMode>
            <!--<legacyMode>true</legacyMode>-->
            <rosDebugLevel>na</rosDebugLevel>
        </plugin>
    </gazebo>
    <gazebo reference="laser_sensor_link">
        <sensor name="laser_sensor" type="gpu_ray">
            <pose>0 0 0 0 0 0</pose>
            <visualize>false</visualize>
            <!--<visualize>true</visualize>-->
            <update_rate>40</update_rate>
            <ray>
                <scan>
                    <horizontal>
                        <samples>720</samples>
                        <resolution>1</resolution>
                        <min_angle>-1.570796</min_angle>
                        <max_angle>1.570796</max_angle>
                    </horizontal>
                </scan>
                <range>
                    <min>0.10</min>
                    <max>30.0</max>
                    <resolution>0.01</resolution>
                </range>
                <noise>
                    <type>gaussian</type>
                    <mean>0.0</mean>
                    <stddev>0.01</stddev>
                </noise>
            </ray>
            <plugin filename="libgazebo_ros_gpu_laser.so" name="gazebo_ros_head_hokuyo_controller">
                <topicName>/kobuki/laser/scan</topicName>
                <frameName>laser_sensor_link</frameName>
            </plugin>
        </sensor>
    </gazebo>
    <!--gazebo>
	    <plugin name="kobuki_controller" filename="libgazebo_ros_kobuki.so">
	      <publish_tf>1</publish_tf>
	      <left_wheel_joint_name>wheel_left_joint</left_wheel_joint_name>
	      <right_wheel_joint_name>wheel_right_joint</right_wheel_joint_name>
	      <wheel_separation>.230</wheel_separation>
	      <wheel_diameter>0.070</wheel_diameter>
	      <torque>1.0</torque>
	      <velocity_command_timeout>0.6</velocity_command_timeout>
	      <cliff_sensor_left_name>cliff_sensor_left</cliff_sensor_left_name>
	      <cliff_sensor_center_name>cliff_sensor_front</cliff_sensor_center_name>
	      <cliff_sensor_right_name>cliff_sensor_right</cliff_sensor_right_name>
	      <cliff_detection_threshold>0.04</cliff_detection_threshold>
	      <bumper_name>bumpers</bumper_name>
        <imu_name>imu</imu_name>
	    </plugin>
	  </gazebo-->
    <joint name="pole_bottom_0_joint" type="fixed">
        <origin rpy="0 0 0" xyz="0.12 0.082 0.1028" />
        <parent link="base_link" />
        <child link="pole_bottom_0_link" />
    </joint>
    <link name="pole_bottom_0_link">
        <visual>
            <origin rpy="0 0 0" xyz="0 0 0" />
            <geometry>
                <mesh filename="package://turtlex_description/meshes/stacks/pole_bottom_reexport.dae" />
            </geometry>
        </visual>
        <collision>
            <origin rpy="0 0 0" xyz="0 0 0" />
            <geometry>
                <cylinder length="0.0492" radius="0.006" />
            </geometry>
        </collision>
        
<inertial>
            <mass value="0.008" />
            <origin rpy="0 0 0" xyz="0 0 0" />
            <inertia ixx="0.000001686" ixy="0.0" ixz="0.0" iyy="0.000001686" iyz="0.0" izz="0.000000144" />
        </inertial>

    </link>
    <joint name="pole_bottom_1_joint" type="fixed">
        <origin rpy="0 0 0" xyz="0.055 0.12 0.1028" />
        <parent link="base_link" />
        <child link="pole_bottom_1_link" />
    </joint>
    <link name="pole_bottom_1_link">
        <visual>
            <origin rpy="0 0 0" xyz="0 0 0" />
            <geometry>
                <mesh filename="package://turtlex_description/meshes/stacks/pole_bottom_reexport.dae" />
            </geometry>
        </visual>
        <collision>
            <origin rpy="0 0 0" xyz="0 0 0" />
            <geometry>
                <cylinder length="0.0492" radius="0.006" />
            </geometry>
        </collision>
        
<inertial>
            <mass value="0.008" />
            <origin rpy="0 0 0" xyz="0 0 0" />
            <inertia ixx="0.000001686" ixy="0.0" ixz="0.0" iyy="0.000001686" iyz="0.0" izz="0.000000144" />
        </inertial>

    </link>
    <joint name="pole_bottom_2_joint" type="fixed">
        <origin rpy="0 0 0" xyz="-0.055 0.12 0.1028" />
        <parent link="base_link" />
        <child link="pole_bottom_2_link" />
    </joint>
    <link name="pole_bottom_2_link">
        <visual>
            <origin rpy="0 0 0" xyz="0 0 0" />
            <geometry>
                <mesh filename="package://turtlex_description/meshes/stacks/pole_bottom_reexport.dae" />
            </geometry>
        </visual>
        <collision>
            <origin rpy="0 0 0" xyz="0 0 0" />
            <geometry>
                <cylinder length="0.0492" radius="0.006" />
            </geometry>
        </collision>
        
<inertial>
            <mass value="0.008" />
            <origin rpy="0 0 0" xyz="0 0 0" />
            <inertia ixx="0.000001686" ixy="0.0" ixz="0.0" iyy="0.000001686" iyz="0.0" izz="0.000000144" />
        </inertial>

    </link>
    <joint name="pole_bottom_3_joint" type="fixed">
        <origin rpy="0 0 0" xyz="0.12 -0.082 0.1028" />
        <parent link="base_link" />
        <child link="pole_bottom_3_link" />
    </joint>
    <link name="pole_bottom_3_link">
        <visual>
            <origin rpy="0 0 0" xyz="0 0 0" />
            <geometry>
                <mesh filename="package://turtlex_description/meshes/stacks/pole_bottom_reexport.dae" />
            </geometry>
        </visual>
        <collision>
            <origin rpy="0 0 0" xyz="0 0 0" />
            <geometry>
                <cylinder length="0.0492" radius="0.006" />
            </geometry>
        </collision>
        
<inertial>
            <mass value="0.008" />
            <origin rpy="0 0 0" xyz="0 0 0" />
            <inertia ixx="0.000001686" ixy="0.0" ixz="0.0" iyy="0.000001686" iyz="0.0" izz="0.000000144" />
        </inertial>

    </link>
    <joint name="pole_bottom_4_joint" type="fixed">
        <origin rpy="0 0 0" xyz="0.055 -0.12 0.1028" />
        <parent link="base_link" />
        <child link="pole_bottom_4_link" />
    </joint>
    <link name="pole_bottom_4_link">
        <visual>
            <origin rpy="0 0 0" xyz="0 0 0" />
            <geometry>
                <mesh filename="package://turtlex_description/meshes/stacks/pole_bottom_reexport.dae" />
            </geometry>
        </visual>
        <collision>
            <origin rpy="0 0 0" xyz="0 0 0" />
            <geometry>
                <cylinder length="0.0492" radius="0.006" />
            </geometry>
        </collision>
        
<inertial>
            <mass value="0.008" />
            <origin rpy="0 0 0" xyz="0 0 0" />
            <inertia ixx="0.000001686" ixy="0.0" ixz="0.0" iyy="0.000001686" iyz="0.0" izz="0.000000144" />
        </inertial>

    </link>
    <joint name="pole_bottom_5_joint" type="fixed">
        <origin rpy="0 0 0" xyz="-0.055 -0.12 0.1028" />
        <parent link="base_link" />
        <child link="pole_bottom_5_link" />
    </joint>
    <link name="pole_bottom_5_link">
        <visual>
            <origin rpy="0 0 0" xyz="0 0 0" />
            <geometry>
                <mesh filename="package://turtlex_description/meshes/stacks/pole_bottom_reexport.dae" />
            </geometry>
        </visual>
        <collision>
            <origin rpy="0 0 0" xyz="0 0 0" />
            <geometry>
                <cylinder length="0.0492" radius="0.006" />
            </geometry>
        </collision>
        
<inertial>
            <mass value="0.008" />
            <origin rpy="0 0 0" xyz="0 0 0" />
            <inertia ixx="0.000001686" ixy="0.0" ixz="0.0" iyy="0.000001686" iyz="0.0" izz="0.000000144" />
        </inertial>

    </link>
    <joint name="plate_bottom_joint" type="fixed">
        <origin rpy="0 0 0" xyz="0.02364 0.0 0.1306" />
        <parent link="base_link" />
        <child link="plate_bottom_link" />
    </joint>
    <link name="plate_bottom_link">
        <visual>
            <origin rpy="0 0 0" xyz="0 0 0" />
            <geometry>
                <mesh filename="package://turtlex_description/meshes/stacks/plate_bottom_reexport.dae" />
            </geometry>
        </visual>
        <collision>
            <origin rpy="0 0 0" xyz="-0.02364 0 0" />
            <geometry>
                <cylinder length="0.006" radius="0.170" />
            </geometry>
        </collision>
        
<inertial>
            <mass value="0.520" />
            <origin xyz="0 0 0" />
            <inertia ixx="0.003328" ixy="0.0" ixz="0.0" iyy="0.003328" iyz="0.0" izz="0.006656" />
        </inertial>

    </link>
    <!--<xacro:stack_middle_pole parent="${parent}" number="0" x_loc= "0.0381" y_loc= "0.1505" z_loc="0.1640"/>-->
    <!--<xacro:stack_middle_pole parent="${parent}" number="1" x_loc= "0.0381" y_loc="-0.1505" z_loc="0.1640"/>-->
    <!--<xacro:stack_middle_pole parent="${parent}" number="2" x_loc="-0.0381" y_loc= "0.1505" z_loc="0.1640"/>-->
    <!--<xacro:stack_middle_pole parent="${parent}" number="3" x_loc="-0.0381" y_loc="-0.1505" z_loc="0.1640"/>-->
    <!--<joint name="plate_middle_joint" type="fixed">
      <origin xyz="-0.01364 0.0 0.1874" rpy="0 0 0"/>
      <parent link="${parent}"/>
      <child link="plate_middle_link"/>
    </joint>  
    <link name="plate_middle_link">
      <visual>
        <origin xyz="0 0 0" rpy="0 0 0"/>
        <geometry>
          <mesh filename="package://turtlex_description/meshes/stacks/plate_middle_reexport.dae"/>
        </geometry>
      </visual>  
      <collision>
        <origin xyz="0.01364 0.0 0.0" rpy="0 0 0"/>
        <geometry>
          <cylinder length="0.006" radius="0.170"/>
        </geometry>
      </collision>
      
<inertial>
        <mass value="0.520" />
        <origin xyz="0 0 0" />
        <inertia ixx="0.003328" ixy="0.0" ixz="0.0"
                 iyy="0.003328" iyz="0.0"
                 izz="0.006656" />
      </inertial>
  
    </link>-->
    <!--<xacro:stack_top_pole parent="${parent}" number="0" x_loc= "0.0381" y_loc= "0.1505" z_loc="0.2920"/>-->
    <!--<xacro:stack_top_pole parent="${parent}" number="1" x_loc= "0.0381" y_loc="-0.1505" z_loc="0.2920"/>-->
    <!--<xacro:stack_top_pole parent="${parent}" number="2" x_loc="-0.0381" y_loc= "0.1505" z_loc="0.2920"/>-->
    <!--<xacro:stack_top_pole parent="${parent}" number="3" x_loc="-0.0381" y_loc="-0.1505" z_loc="0.2920"/>-->
    <!--<xacro:stack_3d_sensor_pole parent="${parent}" number="0" x_loc="-0.1024" y_loc= "0.098" z_loc="0.2372"/>-->
    <!--<xacro:stack_3d_sensor_pole parent="${parent}" number="1" x_loc="-0.1024" y_loc="-0.098" z_loc="0.2372"/>-->
    <!--<joint name="plate_top_joint" type="fixed">
      <origin xyz="-0.01364 0.0  0.3966" rpy="0 0 0"/>
      <parent link="${parent}"/>
      <child link="plate_top_link"/>
    </joint>  
    <link name="plate_top_link">
      <visual>
        <origin xyz="0 0 0" rpy="0 0 0"/>
        <geometry>
          <mesh filename="package://turtlex_description/meshes/stacks/plate_top_reexport.dae"/>
        </geometry>
      </visual>  
      <collision>
        <origin xyz="0.01364 0 0" rpy="0 0 0"/>
        <geometry>
          <cylinder length="0.006" radius="0.170"/>
        </geometry>
      </collision>
      
<inertial>
        <mass value="0.520"/>
        <origin xyz="0 0 0"/>
        <inertia ixx="0.003328" ixy="0.0" ixz="0.0"
                 iyy="0.003328" iyz="0.0"
                 izz="0.006656" />
      </inertial>

    </link>-->
    <joint name="camera_rgb_joint" type="fixed">
        <origin rpy="0 0 0" xyz="0.174 0.0225 0.108" />
        <parent link="base_link" />
        <child link="camera_rgb_frame" />
    </joint>
    <link name="camera_rgb_frame" />
    <joint name="camera_rgb_optical_joint" type="fixed">
        <origin rpy="-1.5707963267948966 0 -1.5707963267948966" xyz="0 0 0" />
        <parent link="camera_rgb_frame" />
        <child link="camera_rgb_optical_frame" />
    </joint>
    <link name="camera_rgb_optical_frame" />
    <joint name="camera_joint" type="fixed">
        <origin rpy="0 0 0" xyz="0 -0.022 0" />
        <parent link="camera_rgb_frame" />
        <child link="camera_link" />
    </joint>
    <link name="camera_link">
        <visual>
            <origin rpy="0 0 0" xyz="-0.015 0.0035 0.004" />
            <geometry>
                <mesh filename="package://turtlex_description/meshes/sensors/xtion_pro_camera.dae" />
            </geometry>
        </visual>
        <collision>
            <origin rpy="0 0 0" xyz="0.0 0.0 0.0" />
            <geometry>
                <!--<box size="0.0730 0.2760 0.0720"/>-->
                <box size="0.039 0.19 0.032" />
            </geometry>
        </collision>
        
<inertial>
            <mass value="0.170" />
            <origin xyz="0 0 0" />
            <inertia ixx="0.001152600" ixy="0.0" ixz="0.0" iyy="0.000148934" iyz="0.0" izz="0.001154654" />
        </inertial>

    </link>
    <joint name="camera_depth_joint" type="fixed">
        <origin rpy="0 0 0" xyz="0 0.027 0" />
        <parent link="camera_rgb_frame" />
        <child link="camera_depth_frame" />
    </joint>
    <link name="camera_depth_frame" />
    <joint name="camera_depth_optical_joint" type="fixed">
        <origin rpy="-1.5707963267948966 0 -1.5707963267948966" xyz="0 0 0" />
        <parent link="camera_depth_frame" />
        <child link="camera_depth_optical_frame" />
    </joint>
    <link name="camera_depth_optical_frame" />
    <!-- RGBD sensor for simulation -->
    <asus_xtion_pro_sim_3dsensor />
    <!-- Asus mount -->
    <joint name="mount_asus_xtion_pro_joint" type="fixed">
        <!--<origin xyz="-0.1024 0.0 0.272" rpy="0 0 0"/>-->
        <origin rpy="0 0 0" xyz="0.155 0.0 0.0826" />
        <parent link="base_link" />
        <child link="mount_asus_xtion_pro_link" />
    </joint>
    <link name="mount_asus_xtion_pro_link">
        <visual>
            <origin rpy="-1.5707963267948966 0 0" xyz="0 0 0" />
            <geometry>
                <mesh filename="package://turtlex_description/meshes/sensors/xtion_pro_stack.dae" />
            </geometry>
        </visual>
        <collision>
            <origin rpy="0 0 0" xyz="0.0 0.0 0.0" />
            <geometry>
                <!--<box size="0.0330 0.2760 0.0120"/>-->
                <box size="0.0330 0.2260 0.0120" />
            </geometry>
        </collision>
        
<inertial>
            <mass value="0.170" />
            <origin xyz="0 0 0" />
            <inertia ixx="0.001152600" ixy="0.0" ixz="0.0" iyy="0.000148934" iyz="0.0" izz="0.001154654" />
        </inertial>

    </link>
    <!--link name="plate_top_link"/-->
    <!--joint name="fixed" type="fixed">
      <parent link="plate_top_link" />
      <child link="ph_base_link" />
   </joint-->
    <transmission name="tran1">
        <type>transmission_interface/SimpleTransmission</type>
        <joint name="joint_1">
            <hardwareInterface>hardware_interface/EffortJointInterface</hardwareInterface>
        </joint>
        <actuator name="motor1">
            <mechanicalReduction>1</mechanicalReduction>
        </actuator>
    </transmission>
    <transmission name="tran2">
        <type>transmission_interface/SimpleTransmission</type>
        <joint name="joint_2">
            <hardwareInterface>hardware_interface/EffortJointInterface</hardwareInterface>
        </joint>
        <actuator name="motor2">
            <mechanicalReduction>1</mechanicalReduction>
        </actuator>
    </transmission>
    <transmission name="tran3">
        <type>transmission_interface/SimpleTransmission</type>
        <joint name="joint_3">
            <hardwareInterface>hardware_interface/EffortJointInterface</hardwareInterface>
        </joint>
        <actuator name="motor3">
            <mechanicalReduction>1</mechanicalReduction>
        </actuator>
    </transmission>
    <transmission name="tran4">
        <type>transmission_interface/SimpleTransmission</type>
        <joint name="joint_4">
            <hardwareInterface>hardware_interface/EffortJointInterface</hardwareInterface>
        </joint>
        <actuator name="motor4">
            <mechanicalReduction>1</mechanicalReduction>
        </actuator>
    </transmission>
    <transmission name="tran5">
        <type>transmission_interface/SimpleTransmission</type>
        <joint name="joint_5">
            <hardwareInterface>hardware_interface/EffortJointInterface</hardwareInterface>
        </joint>
        <actuator name="motor5">
            <mechanicalReduction>1</mechanicalReduction>
        </actuator>
    </transmission>
    <transmission name="tran6">
        <type>transmission_interface/SimpleTransmission</type>
        <joint name="gripper_prismatic_joint_1">
            <!--<joint name="gripper_joint">-->
            <hardwareInterface>hardware_interface/EffortJointInterface</hardwareInterface>
        </joint>
        <actuator name="motor6">
            <mechanicalReduction>1</mechanicalReduction>
        </actuator>
    </transmission>
    <transmission name="tran7">
        <type>transmission_interface/SimpleTransmission</type>
        <joint name="gripper_prismatic_joint_2">
            <hardwareInterface>hardware_interface/EffortJointInterface</hardwareInterface>
        </joint>
        <actuator name="motor7">
            <mechanicalReduction>1</mechanicalReduction>
        </actuator>
    </transmission>
    <!-- ros_control plugin -->
    <gazebo>
        <plugin filename="libgazebo_ros_control.so" name="gazebo_ros_control">
            <!--<robotNamespace>/turtlex</robotNamespace>-->
            <robotSimType>gazebo_ros_control/DefaultRobotHWSim</robotSimType>
        </plugin>
    </gazebo>
    <!--<xacro:macro name="mimic_joint_plugin_gazebo" params="name_prefix parent_joint mimic_joint has_pid:=false multiplier:=1.0 offset:=0 sensitiveness:=0.0 max_effort:=1.0 robot_namespace:=''">
    <gazebo>
      <plugin name="${name_prefix}mimic_joint_plugin" filename="libroboticsgroup_gazebo_mimic_joint_plugin.so">
        <joint>${parent_joint}</joint>
        <mimicJoint>${mimic_joint}</mimicJoint>-->
    <!--<xacro:if value="${has_pid}">-->
    <!-- if set to true, PID parameters from "/gazebo_ros_control/pid_gains/${mimic_joint}" are loaded -->
    <!--<hasPID />
        </xacro:if>
        <multiplier>${multiplier}</multiplier>
        <offset>${offset}</offset>-->
    <!--<sensitiveness>${sensitiveness}</sensitiveness>-->
    <!-- if absolute difference between setpoint and process value is below this threshold, do nothing; 0.0 = disable [rad] -->
    <!--<maxEffort>${max_effort}</maxEffort>-->
    <!-- only taken into account if has_pid:=true [Nm] -->
    <!--<xacro:unless value="${robot_namespace == ''}">
          <robotNamespace>${robot_namespace}</robotNamespace>
        </xacro:unless>
      </plugin>
    </gazebo>
  </xacro:macro>-->
    <!--
    potrebbe essere che qui i gazebo reference siano del tipo:
    <kp>1000000.0</kp>
    <kd>100.0</kd>
    <mu1>1.5</mu1>
    <mu2>1.5</mu2>
    <fdir1>1 0 0</fdir1>
    <maxVel>1.0</maxVel>
    <minDepth>0.002</minDepth>
-->
    <!--
  mu1 mu2:
  https://answers.gazebosim.org/question/22301/friction-parameters-mu1-and-mu2-in-gazebo-reference-tag-wrong-description-in-tutorial/
-->
    <gazebo reference="arm_base_link">
        <mu1>0.2</mu1>
        <mu2>0.2</mu2>
        <material>Gazebo/DarkGrey</material>
        <!--<dampingFactor>0.1</dampingFactor>-->
    </gazebo>
    <gazebo reference="shoulder_link">
        <mu1>0.2</mu1>
        <mu2>0.2</mu2>
        <material>Gazebo/Grey</material>
        <!--<dampingFactor>0.1</dampingFactor>-->
    </gazebo>
    <gazebo reference="biceps_link">
        <mu1>0.2</mu1>
        <mu2>0.2</mu2>
        <material>Gazebo/DarkGrey</material>
        <!--<dampingFactor>0.1</dampingFactor>-->
    </gazebo>
    <gazebo reference="forearm_link">
        <mu1>0.2</mu1>
        <mu2>0.2</mu2>
        <material>Gazebo/Grey</material>
        <!--<dampingFactor>0.1</dampingFactor>-->
    </gazebo>
    <gazebo reference="wrist_1_link">
        <mu1>0.2</mu1>
        <mu2>0.2</mu2>
        <material>Gazebo/DarkGrey</material>
        <!--<dampingFactor>0.1</dampingFactor>-->
    </gazebo>
    <gazebo reference="wrist_2_link">
        <mu1>0.2</mu1>
        <mu2>0.2</mu2>
        <material>Gazebo/DarkGrey</material>
        <!--<dampingFactor>0.1</dampingFactor>-->
    </gazebo>
    <gazebo reference="gripper_rail_link">
        <mu1>0.2</mu1>
        <mu2>0.2</mu2>
        <material>Gazebo/Grey</material>
        <!--<dampingFactor>0.1</dampingFactor>-->
    </gazebo>
    <!--
    forse conviene mettere a 10 mu1 e mu2 (friction) per i gripper links (o forse mu2 > mu1), vedi qui:
    https://answers.gazebosim.org/question/22301/friction-parameters-mu1-and-mu2-in-gazebo-reference-tag-wrong-description-in-tutorial/
    https://answers.gazebosim.org//question/22303/object-slips-from-gripper-fingers-when-grasping-in-simulation/
  -->
    <gazebo reference="gripper_1_link">
        <!--<mu1>0.2</mu1>-->
        <!--<mu2>0.2</mu2>-->
        <kp>1000000.0</kp>
        <kd>100.0</kd>
        <mu1>30.0</mu1>
        <mu2>30.0</mu2>
        <maxVel>1.0</maxVel>
        <minDepth>0.001</minDepth>
        <material>Gazebo/Grey</material>
        <!--<dampingFactor>0.1</dampingFactor>-->
    </gazebo>
    <gazebo reference="gripper_2_link">
        <!--<mu1>0.2</mu1>-->
        <!--<mu2>0.2</mu2>-->
        <kp>1000000.0</kp>
        <kd>100.0</kd>
        <mu1>30.0</mu1>
        <mu2>30.0</mu2>
        <maxVel>1.0</maxVel>
        <minDepth>0.001</minDepth>
        <material>Gazebo/Grey</material>
        <!--<dampingFactor>0.1</dampingFactor>-->
    </gazebo>
    <!-- links -->
    <link name="arm_base_link">
        <visual>
            <origin rpy="0 0 0" xyz="0 0 0" />
            <geometry>
                <mesh filename="package://turtlex_description/meshes/arm/base_link.stl" />
            </geometry>
            <material name="">
                <color rgba="0.15 0.15 0.15 1.0" />
            </material>
        </visual>
        <collision>
            <origin rpy="0 0 0" xyz="0 0 0" />
            <geometry>
                <mesh filename="package://turtlex_description/meshes/arm/base_link.stl" />
            </geometry>
        </collision>
        
<inertial>
            <origin rpy="0 0 0" xyz="0 0 0" />
            <mass value="0.379673" />
            <inertia ixx="0.0004351000" ixy="0.0000000707" ixz="0.0000000266" iyy="0.0004452000" iyz="-0.0000022881" izz="0.0005731000" />
        </inertial>

    </link>
    <link name="shoulder_link">
        <visual>
            <origin rpy="0 0 0" xyz="0 0 0" />
            <geometry>
                <mesh filename="package://turtlex_description/meshes/arm/shoulder_link.stl" />
            </geometry>
            <material name="">
                <color rgba="0.15 0.15 0.15 1.0" />
            </material>
        </visual>
        <collision>
            <origin rpy="0 0 0" xyz="0 0 0" />
            <geometry>
                <mesh filename="package://turtlex_description/meshes/arm/shoulder_link.stl" />
            </geometry>
        </collision>
        
<inertial>
            <origin rpy="0 0 0" xyz="0 0 0" />
            <mass value="0.072587" />
            <inertia ixx="0.0000231000" ixy="0.0000000003" ixz="0.0000001606" iyy="0.0000253500" iyz="-0.0000000206" izz="0.0000144200" />
        </inertial>

    </link>
    <link name="biceps_link">
        <visual>
            <origin rpy="0 0 0" xyz="0 0 0" />
            <geometry>
                <mesh filename="package://turtlex_description/meshes/arm/biceps_link.new.stl" />
            </geometry>
            <material name="">
                <color rgba="0.15 0.15 0.15 1.0" />
            </material>
        </visual>
        <collision>
            <origin rpy="0 0 0" xyz="0 0 0" />
            <geometry>
                <mesh filename="package://turtlex_description/meshes/arm/biceps_link.new.stl" />
            </geometry>
        </collision>
        
<inertial>
            <origin rpy="0 0 0" xyz="0 0 0" />
            <mass value="0.082923" />
            <inertia ixx="0.0000800600" ixy="-0.0000002144" ixz="0.0000002982" iyy="0.0000745900" iyz="0.0000165700" izz="0.0000368500" />
        </inertial>

    </link>
    <link name="forearm_link">
        <visual>
            <origin rpy="0 0 0" xyz="0 0 0" />
            <geometry>
                <mesh filename="package://turtlex_description/meshes/arm/forearm_link.new.stl" />
            </geometry>
            <material name="">
                <color rgba="0.15 0.15 0.15 1.0" />
            </material>
        </visual>
        <collision>
            <origin rpy="0 0 0" xyz="0 0 0" />
            <geometry>
                <mesh filename="package://turtlex_description/meshes/arm/forearm_link.new.stl" />
            </geometry>
        </collision>
        
<inertial>
            <origin rpy="0 0 0" xyz="0 0 0" />
            <mass value="0.073058" />
            <inertia ixx="0.0000533800" ixy="-0.0000003073" ixz="0.0000000000" iyy="0.0000165300" iyz="0.0000000000" izz="0.0000603500" />
        </inertial>

    </link>
    <link name="wrist_1_link">
        <visual>
            <origin rpy="0 0 0" xyz="0 0 0" />
            <geometry>
                <mesh filename="package://turtlex_description/meshes/arm/wrist_1_link.stl" />
            </geometry>
            <material name="">
                <color rgba="0.15 0.15 0.15 1.0" />
            </material>
        </visual>
        <collision>
            <origin rpy="0 0 0" xyz="0 0 0" />
            <geometry>
                <mesh filename="package://turtlex_description/meshes/arm/wrist_1_link.stl" />
            </geometry>
        </collision>
        
<inertial>
            <origin rpy="0 0 0" xyz="0 0 0" />
            <mass value="0.069929" />
            <inertia ixx="0.0000226800" ixy="0.0000000000" ixz="0.0000000000" iyy="0.0000204400" iyz="0.0000008485" izz="0.0000197400" />
        </inertial>

    </link>
    <link name="wrist_2_link">
        <visual>
            <origin rpy="0 0 0" xyz="0 0 0" />
            <geometry>
                <mesh filename="package://turtlex_description/meshes/arm/wrist_2_link.new.stl" />
            </geometry>
            <material name="">
                <color rgba="0.15 0.15 0.15 1.0" />
            </material>
        </visual>
        <collision>
            <origin rpy="0 0 0" xyz="0 0 0" />
            <geometry>
                <mesh filename="package://turtlex_description/meshes/arm/wrist_2_link.new.stl" />
            </geometry>
        </collision>
        
<inertial>
            <origin rpy="0 0 0" xyz="0 0 0" />
            <mass value="0.069929" />
            <inertia ixx="0.0000226800" ixy="0.0000000000" ixz="0.0000000000" iyy="0.0000204400" iyz="0.0000008485" izz="0.0000197400" />
        </inertial>

    </link>
    <!-- joints -->
    <joint name="arm_base_joint" type="fixed">
        <origin rpy="0.0 0.0 0.0" xyz="-0.007 0.0 0.0" />
        <parent link="plate_bottom_link" />
        <child link="arm_base_link" />
    </joint>
    <joint name="joint_1" type="revolute">
        <origin rpy="0 0 0" xyz="0 0 0.125" />
        <parent link="arm_base_link" />
        <child link="shoulder_link" />
        <axis xyz="0 0 1" />
        <limit effort="6" lower="-2.617" upper="2.617" velocity="0.785" />
        <dynamics friction="0.1" />
        <!--<limit lower="-2.617" upper="2.617" effort="10000" velocity="0.785" />-->
    </joint>
    <joint name="joint_2" type="revolute">
        <!--origin xyz="0.04825 0 0.14203" rpy="0 0 0" /-->
        <origin rpy="0 0 0" xyz="0 0 0" />
        <parent link="shoulder_link" />
        <child link="biceps_link" />
        <axis xyz="0 1 0" />
        <limit effort="6" lower="-1.571" upper="1.571" velocity="1.571" />
        <dynamics friction="0.1" />
        <!--<limit lower="-1.571" upper="1.571" effort="10000" velocity="1.571" />-->
    </joint>
    <joint name="joint_3" type="revolute">
        <origin rpy="0 1.5707963267948966 0" xyz="0.04825 0 0.14203000000000002" />
        <parent link="biceps_link" />
        <child link="forearm_link" />
        <axis xyz="0 1 0" />
        <limit effort="6" lower="-1.571" upper="1.571" velocity="1.571" />
        <dynamics friction="0.1" />
        <!--<limit lower="-1.571" upper="1.571" effort="10000" velocity="1.571" />-->
    </joint>
    <joint name="joint_4" type="revolute">
        <origin rpy="0 0 0" xyz="0 0 0.14203000000000002" />
        <parent link="forearm_link" />
        <child link="wrist_1_link" />
        <axis xyz="0 1 0" />
        <limit effort="6" lower="-1.745" upper="1.745" velocity="1.571" />
        <dynamics friction="0.1" />
        <!--<limit lower="-1.745" upper="1.745" effort="10000" velocity="1.571" />-->
    </joint>
    <joint name="joint_5" type="revolute">
        <origin rpy="0 0 0" xyz="0 0 0.07150000000000001" />
        <parent link="wrist_1_link" />
        <child link="wrist_2_link" />
        <axis xyz="0 0 1" />
        <limit effort="6" lower="-2.617" upper="2.617" velocity="1.571" />
        <dynamics friction="0.1" />
        <!--<limit lower="-2.617" upper="2.617" effort="10000" velocity="1.571" />-->
    </joint>
    <!-- Gripper -->
    <!--<xacro:include filename="$(find turtlex_description)/urdf/widowx_gripper.xacro"/>-->
    <link name="gripper_rail_link">
        <visual>
            <origin rpy="0 0 1.57" xyz="0 0 0" />
            <geometry>
                <mesh filename="package://turtlex_description/meshes/arm/gripper_rail_link.stl" />
            </geometry>
            <material name="">
                <color rgba="0.15 0.15 0.15 1.0" />
            </material>
        </visual>
        <collision>
            <origin rpy="0 0 1.57" xyz="0 0 0" />
            <geometry>
                <mesh filename="package://turtlex_description/meshes/arm/gripper_rail_link.stl" />
            </geometry>
        </collision>
        
<inertial>
            <origin rpy="0 0 0" xyz="0 0 0" />
            <mass value="0.001" />
            <inertia ixx="0.001" ixy="0" ixz="0" iyy="0.001" iyz="0" izz="0.001" />
        </inertial>

    </link>
    <link name="gripper_1_link">
        <visual>
            <origin rpy="0 0 1.57" xyz="0 -0.0007 0" />
            <geometry>
                <mesh filename="package://turtlex_description/meshes/arm/gripper_hand_fixed_link.stl" />
            </geometry>
            <material name="">
                <color rgba="0.15 0.15 0.15 1.0" />
            </material>
        </visual>
        <collision>
            <origin rpy="0 0 1.57" xyz="0 -0.0007 0" />
            <geometry>
                <mesh filename="package://turtlex_description/meshes/arm/gripper_hand_fixed_link.stl" />
            </geometry>
        </collision>
        
<inertial>
            <origin rpy="0 0 0" xyz="0 0 0" />
            <mass value="0.016246" />
            <inertia ixx="0.0000047310" ixy="0.0000004560" ixz="0.0000000000" iyy="0.0000015506" iyz="0.0000000000" izz="0.0000037467" />
        </inertial>

    </link>
    <link name="gripper_2_link">
        <visual>
            <origin rpy="0 0 -1.57" xyz="0 0.0007 0" />
            <geometry>
                <mesh filename="package://turtlex_description/meshes/arm/gripper_hand_fixed_link.stl" />
            </geometry>
            <material name="">
                <color rgba="0.15 0.15 0.15 1.0" />
            </material>
        </visual>
        <collision>
            <origin rpy="0 0 -1.57" xyz="0 0.0007 0" />
            <geometry>
                <mesh filename="package://turtlex_description/meshes/arm/gripper_hand_fixed_link.stl" />
            </geometry>
        </collision>
        
<inertial>
            <origin rpy="0 0 0" xyz="0 0 0" />
            <mass value="0.016246" />
            <inertia ixx="0.0000047310" ixy="0.0000004560" ixz="0.0000000000" iyy="0.0000015506" iyz="0.0000000000" izz="0.0000037467" />
        </inertial>

    </link>
    <joint name="joint_6" type="fixed">
        <origin rpy="0 0 0" xyz="0 0 0.043000000000000003" />
        <parent link="wrist_2_link" />
        <child link="gripper_rail_link" />
        <axis xyz="0 0 1" />
    </joint>
    <joint name="gripper_prismatic_joint_1" type="prismatic">
        <origin rpy="0 0 0" xyz="0 0 0" />
        <parent link="gripper_rail_link" />
        <child link="gripper_1_link" />
        <axis xyz="0 -1 0" />
        <limit effort="6" lower="0.002" upper="0.031" velocity="0.5" />
        <!-- lower="0" upper="0.027"  ? -->
        <!--<limit lower="0.002" upper="0.031" effort="10000" velocity="0.5" />-->
        <dynamics friction="0.1" />
    </joint>
    <joint name="gripper_prismatic_joint_2" type="prismatic">
        <origin rpy="0 0 0" xyz="0 0 0" />
        <parent link="gripper_rail_link" />
        <child link="gripper_2_link" />
        <!--<mimic joint="gripper_prismatic_joint_1" multiplier="-1" offset="0"/>-->
        <axis xyz="0 1 0" />
        <limit effort="6" lower="0.002" upper="0.031" velocity="0.5" />
        <!-- lower="0" upper="0.027"  ? -->
        <!--<limit lower="0.002" upper="0.031" effort="10000" velocity="0.5" />-->
        <dynamics friction="0.1" />
    </joint>
    <!--<xacro:mimic_joint_plugin_gazebo name_prefix="gripper_prismatic_joint_2"
         parent_joint="gripper_prismatic_joint_1" mimic_joint="gripper_prismatic_joint_2"
         has_pid="true" multiplier="-1.0" max_effort="6" />-->
    <transmission name="trans_wheel_left_joint">
        <type>transmission_interface/SimpleTransmission</type>
        <joint name="wheel_left_joint">
            <hardwareInterface>hardware_interface/EffortJointInterface</hardwareInterface>
        </joint>
        <actuator name="wheel_left_joint_motor">
            <hardwareInterface>hardware_interface/EffortJointInterface</hardwareInterface>
            <mechanicalReduction>1</mechanicalReduction>
        </actuator>
    </transmission>
    <transmission name="trans_wheel_right_joint">
        <type>transmission_interface/SimpleTransmission</type>
        <joint name="wheel_right_joint">
            <hardwareInterface>hardware_interface/EffortJointInterface</hardwareInterface>
        </joint>
        <actuator name="wheel_right_joint_motor">
            <hardwareInterface>hardware_interface/EffortJointInterface</hardwareInterface>
            <mechanicalReduction>1</mechanicalReduction>
        </actuator>
    </transmission>
    <transmission name="trans_joint_1">
        <type>transmission_interface/SimpleTransmission</type>
        <joint name="joint_1">
            <hardwareInterface>hardware_interface/EffortJointInterface</hardwareInterface>
        </joint>
        <actuator name="joint_1_motor">
            <hardwareInterface>hardware_interface/EffortJointInterface</hardwareInterface>
            <mechanicalReduction>1</mechanicalReduction>
        </actuator>
    </transmission>
    <transmission name="trans_joint_2">
        <type>transmission_interface/SimpleTransmission</type>
        <joint name="joint_2">
            <hardwareInterface>hardware_interface/EffortJointInterface</hardwareInterface>
        </joint>
        <actuator name="joint_2_motor">
            <hardwareInterface>hardware_interface/EffortJointInterface</hardwareInterface>
            <mechanicalReduction>1</mechanicalReduction>
        </actuator>
    </transmission>
    <transmission name="trans_joint_3">
        <type>transmission_interface/SimpleTransmission</type>
        <joint name="joint_3">
            <hardwareInterface>hardware_interface/EffortJointInterface</hardwareInterface>
        </joint>
        <actuator name="joint_3_motor">
            <hardwareInterface>hardware_interface/EffortJointInterface</hardwareInterface>
            <mechanicalReduction>1</mechanicalReduction>
        </actuator>
    </transmission>
    <transmission name="trans_joint_4">
        <type>transmission_interface/SimpleTransmission</type>
        <joint name="joint_4">
            <hardwareInterface>hardware_interface/EffortJointInterface</hardwareInterface>
        </joint>
        <actuator name="joint_4_motor">
            <hardwareInterface>hardware_interface/EffortJointInterface</hardwareInterface>
            <mechanicalReduction>1</mechanicalReduction>
        </actuator>
    </transmission>
    <transmission name="trans_joint_5">
        <type>transmission_interface/SimpleTransmission</type>
        <joint name="joint_5">
            <hardwareInterface>hardware_interface/EffortJointInterface</hardwareInterface>
        </joint>
        <actuator name="joint_5_motor">
            <hardwareInterface>hardware_interface/EffortJointInterface</hardwareInterface>
            <mechanicalReduction>1</mechanicalReduction>
        </actuator>
    </transmission>
    <transmission name="trans_gripper_prismatic_joint_1">
        <type>transmission_interface/SimpleTransmission</type>
        <joint name="gripper_prismatic_joint_1">
            <hardwareInterface>hardware_interface/EffortJointInterface</hardwareInterface>
        </joint>
        <actuator name="gripper_prismatic_joint_1_motor">
            <hardwareInterface>hardware_interface/EffortJointInterface</hardwareInterface>
            <mechanicalReduction>1</mechanicalReduction>
        </actuator>
    </transmission>
    <transmission name="trans_gripper_prismatic_joint_2">
        <type>transmission_interface/SimpleTransmission</type>
        <joint name="gripper_prismatic_joint_2">
            <hardwareInterface>hardware_interface/EffortJointInterface</hardwareInterface>
        </joint>
        <actuator name="gripper_prismatic_joint_2_motor">
            <hardwareInterface>hardware_interface/EffortJointInterface</hardwareInterface>
            <mechanicalReduction>1</mechanicalReduction>
        </actuator>
    </transmission>
    <gazebo>
        <plugin name="gazebo_ros_control" filename="libgazebo_ros_control.so">
            <robotNamespace>/</robotNamespace>
        </plugin>
    </gazebo>
</robot>

<transmission name="tran1">
        <type>transmission_interface/SimpleTransmission</type>
        <joint name="joint_1">
            <hardwareInterface>hardware_interface/EffortJointInterface</hardwareInterface>
        </joint>
        <actuator name="motor1">
            <mechanicalReduction>1</mechanicalReduction>
        </actuator>
    </transmission>
    <transmission name="tran2">
        <type>transmission_interface/SimpleTransmission</type>
        <joint name="joint_2">
            <hardwareInterface>hardware_interface/EffortJointInterface</hardwareInterface>
        </joint>
        <actuator name="motor2">
            <mechanicalReduction>1</mechanicalReduction>
        </actuator>
    </transmission>
    <transmission name="tran3">
        <type>transmission_interface/SimpleTransmission</type>
        <joint name="joint_3">
            <hardwareInterface>hardware_interface/EffortJointInterface</hardwareInterface>
        </joint>
        <actuator name="motor3">
            <mechanicalReduction>1</mechanicalReduction>
        </actuator>
    </transmission>
    <transmission name="tran4">
        <type>transmission_interface/SimpleTransmission</type>
        <joint name="joint_4">
            <hardwareInterface>hardware_interface/EffortJointInterface</hardwareInterface>
        </joint>
        <actuator name="motor4">
            <mechanicalReduction>1</mechanicalReduction>
        </actuator>
    </transmission>
    <transmission name="tran5">
        <type>transmission_interface/SimpleTransmission</type>
        <joint name="joint_5">
            <hardwareInterface>hardware_interface/EffortJointInterface</hardwareInterface>
        </joint>
        <actuator name="motor5">
            <mechanicalReduction>1</mechanicalReduction>
        </actuator>
    </transmission>
    <transmission name="tran6">
        <type>transmission_interface/SimpleTransmission</type>
        <joint name="gripper_prismatic_joint_1">
            <!--<joint name="gripper_joint">-->
            <hardwareInterface>hardware_interface/EffortJointInterface</hardwareInterface>
        </joint>
        <actuator name="motor6">
            <mechanicalReduction>1</mechanicalReduction>
        </actuator>
    </transmission>
    <transmission name="tran7">
        <type>transmission_interface/SimpleTransmission</type>
        <joint name="gripper_prismatic_joint_2">
            <hardwareInterface>hardware_interface/EffortJointInterface</hardwareInterface>
        </joint>
        <actuator name="motor7">
            <mechanicalReduction>1</mechanicalReduction>
        </actuator>
    </transmission>
    <!-- ros_control plugin -->
    <gazebo>
        <plugin filename="libgazebo_ros_control.so" name="gazebo_ros_control">
            <!--<robotNamespace>/turtlex</robotNamespace>-->
            <robotSimType>gazebo_ros_control/DefaultRobotHWSim</robotSimType>
        </plugin>
    </gazebo>
    <!--<xacro:macro name="mimic_joint_plugin_gazebo" params="name_prefix parent_joint mimic_joint has_pid:=false multiplier:=1.0 offset:=0 sensitiveness:=0.0 max_effort:=1.0 robot_namespace:=''">
    <gazebo>
      <plugin name="${name_prefix}mimic_joint_plugin" filename="libroboticsgroup_gazebo_mimic_joint_plugin.so">
        <joint>${parent_joint}</joint>
        <mimicJoint>${mimic_joint}</mimicJoint>-->
    <!--<xacro:if value="${has_pid}">-->
    <!-- if set to true, PID parameters from "/gazebo_ros_control/pid_gains/${mimic_joint}" are loaded -->
    <!--<hasPID />
        </xacro:if>
        <multiplier>${multiplier}</multiplier>
        <offset>${offset}</offset>-->
    <!--<sensitiveness>${sensitiveness}</sensitiveness>-->
    <!-- if absolute difference between setpoint and process value is below this threshold, do nothing; 0.0 = disable [rad] -->
    <!--<maxEffort>${max_effort}</maxEffort>-->
    <!-- only taken into account if has_pid:=true [Nm] -->
    <!--<xacro:unless value="${robot_namespace == ''}">
          <robotNamespace>${robot_namespace}</robotNamespace>
        </xacro:unless>
      </plugin>
    </gazebo>
  </xacro:macro>-->
    <!--
    potrebbe essere che qui i gazebo reference siano del tipo:
    <kp>1000000.0</kp>
    <kd>100.0</kd>
    <mu1>1.5</mu1>
    <mu2>1.5</mu2>
    <fdir1>1 0 0</fdir1>
    <maxVel>1.0</maxVel>
    <minDepth>0.002</minDepth>
-->
    <!--
  mu1 mu2:
  https://answers.gazebosim.org/question/22301/friction-parameters-mu1-and-mu2-in-gazebo-reference-tag-wrong-description-in-tutorial/
-->
    <gazebo reference="arm_base_link">
        <mu1>0.2</mu1>
        <mu2>0.2</mu2>
        <material>Gazebo/DarkGrey</material>
        <!--<dampingFactor>0.1</dampingFactor>-->
    </gazebo>
    <gazebo reference="shoulder_link">
        <mu1>0.2</mu1>
        <mu2>0.2</mu2>
        <material>Gazebo/Grey</material>
        <!--<dampingFactor>0.1</dampingFactor>-->
    </gazebo>
    <gazebo reference="biceps_link">
        <mu1>0.2</mu1>
        <mu2>0.2</mu2>
        <material>Gazebo/DarkGrey</material>
        <!--<dampingFactor>0.1</dampingFactor>-->
    </gazebo>
    <gazebo reference="forearm_link">
        <mu1>0.2</mu1>
        <mu2>0.2</mu2>
        <material>Gazebo/Grey</material>
        <!--<dampingFactor>0.1</dampingFactor>-->
    </gazebo>
    <gazebo reference="wrist_1_link">
        <mu1>0.2</mu1>
        <mu2>0.2</mu2>
        <material>Gazebo/DarkGrey</material>
        <!--<dampingFactor>0.1</dampingFactor>-->
    </gazebo>
    <gazebo reference="wrist_2_link">
        <mu1>0.2</mu1>
        <mu2>0.2</mu2>
        <material>Gazebo/DarkGrey</material>
        <!--<dampingFactor>0.1</dampingFactor>-->
    </gazebo>
    <gazebo reference="gripper_rail_link">
        <mu1>0.2</mu1>
        <mu2>0.2</mu2>
        <material>Gazebo/Grey</material>
        <!--<dampingFactor>0.1</dampingFactor>-->
    </gazebo>
    <!--
    forse conviene mettere a 10 mu1 e mu2 (friction) per i gripper links (o forse mu2 > mu1), vedi qui:
    https://answers.gazebosim.org/question/22301/friction-parameters-mu1-and-mu2-in-gazebo-reference-tag-wrong-description-in-tutorial/
    https://answers.gazebosim.org//question/22303/object-slips-from-gripper-fingers-when-grasping-in-simulation/
  -->
    <gazebo reference="gripper_1_link">
        <!--<mu1>0.2</mu1>-->
        <!--<mu2>0.2</mu2>-->
        <kp>1000000.0</kp>
        <kd>100.0</kd>
        <mu1>30.0</mu1>
        <mu2>30.0</mu2>
        <maxVel>1.0</maxVel>
        <minDepth>0.001</minDepth>
        <material>Gazebo/Grey</material>
        <!--<dampingFactor>0.1</dampingFactor>-->
    </gazebo>
    <gazebo reference="gripper_2_link">
        <!--<mu1>0.2</mu1>-->
        <!--<mu2>0.2</mu2>-->
        <kp>1000000.0</kp>
        <kd>100.0</kd>
        <mu1>30.0</mu1>
        <mu2>30.0</mu2>
        <maxVel>1.0</maxVel>
        <minDepth>0.001</minDepth>
        <material>Gazebo/Grey</material>
        <!--<dampingFactor>0.1</dampingFactor>-->
    </gazebo>
    <!-- links -->
    <link name="arm_base_link">
        <visual>
            <origin rpy="0 0 0" xyz="0 0 0" />
            <geometry>
                <mesh filename="package://turtlex_description/meshes/arm/base_link.stl" />
            </geometry>
            <material name="">
                <color rgba="0.15 0.15 0.15 1.0" />
            </material>
        </visual>
        <collision>
            <origin rpy="0 0 0" xyz="0 0 0" />
            <geometry>
                <mesh filename="package://turtlex_description/meshes/arm/base_link.stl" />
            </geometry>
        </collision>
        <inertial>
            <origin rpy="0 0 0" xyz="0 0 0" />
            <mass value="0.379673" />
            <inertia ixx="0.0004351000" ixy="0.0000000707" ixz="0.0000000266" iyy="0.0004452000" iyz="-0.0000022881" izz="0.0005731000" />
        </inertial>
    </link>
    <link name="shoulder_link">
        <visual>
            <origin rpy="0 0 0" xyz="0 0 0" />
            <geometry>
                <mesh filename="package://turtlex_description/meshes/arm/shoulder_link.stl" />
            </geometry>
            <material name="">
                <color rgba="0.15 0.15 0.15 1.0" />
            </material>
        </visual>
        <collision>
            <origin rpy="0 0 0" xyz="0 0 0" />
            <geometry>
                <mesh filename="package://turtlex_description/meshes/arm/shoulder_link.stl" />
            </geometry>
        </collision>
        <inertial>
            <origin rpy="0 0 0" xyz="0 0 0" />
            <mass value="0.072587" />
            <inertia ixx="0.0000231000" ixy="0.0000000003" ixz="0.0000001606" iyy="0.0000253500" iyz="-0.0000000206" izz="0.0000144200" />
        </inertial>
    </link>
    <link name="biceps_link">
        <visual>
            <origin rpy="0 0 0" xyz="0 0 0" />
            <geometry>
                <mesh filename="package://turtlex_description/meshes/arm/biceps_link.new.stl" />
            </geometry>
            <material name="">
                <color rgba="0.15 0.15 0.15 1.0" />
            </material>
        </visual>
        <collision>
            <origin rpy="0 0 0" xyz="0 0 0" />
            <geometry>
                <mesh filename="package://turtlex_description/meshes/arm/biceps_link.new.stl" />
            </geometry>
        </collision>
        <inertial>
            <origin rpy="0 0 0" xyz="0 0 0" />
            <mass value="0.082923" />
            <inertia ixx="0.0000800600" ixy="-0.0000002144" ixz="0.0000002982" iyy="0.0000745900" iyz="0.0000165700" izz="0.0000368500" />
        </inertial>
    </link>
    <link name="forearm_link">
        <visual>
            <origin rpy="0 0 0" xyz="0 0 0" />
            <geometry>
                <mesh filename="package://turtlex_description/meshes/arm/forearm_link.new.stl" />
            </geometry>
            <material name="">
                <color rgba="0.15 0.15 0.15 1.0" />
            </material>
        </visual>
        <collision>
            <origin rpy="0 0 0" xyz="0 0 0" />
            <geometry>
                <mesh filename="package://turtlex_description/meshes/arm/forearm_link.new.stl" />
            </geometry>
        </collision>
        <inertial>
            <origin rpy="0 0 0" xyz="0 0 0" />
            <mass value="0.073058" />
            <inertia ixx="0.0000533800" ixy="-0.0000003073" ixz="0.0000000000" iyy="0.0000165300" iyz="0.0000000000" izz="0.0000603500" />
        </inertial>
    </link>
    <link name="wrist_1_link">
        <visual>
            <origin rpy="0 0 0" xyz="0 0 0" />
            <geometry>
                <mesh filename="package://turtlex_description/meshes/arm/wrist_1_link.stl" />
            </geometry>
            <material name="">
                <color rgba="0.15 0.15 0.15 1.0" />
            </material>
        </visual>
        <collision>
            <origin rpy="0 0 0" xyz="0 0 0" />
            <geometry>
                <mesh filename="package://turtlex_description/meshes/arm/wrist_1_link.stl" />
            </geometry>
        </collision>
        <inertial>
            <origin rpy="0 0 0" xyz="0 0 0" />
            <mass value="0.069929" />
            <inertia ixx="0.0000226800" ixy="0.0000000000" ixz="0.0000000000" iyy="0.0000204400" iyz="0.0000008485" izz="0.0000197400" />
        </inertial>
    </link>
    <link name="wrist_2_link">
        <visual>
            <origin rpy="0 0 0" xyz="0 0 0" />
            <geometry>
                <mesh filename="package://turtlex_description/meshes/arm/wrist_2_link.new.stl" />
            </geometry>
            <material name="">
                <color rgba="0.15 0.15 0.15 1.0" />
            </material>
        </visual>
        <collision>
            <origin rpy="0 0 0" xyz="0 0 0" />
            <geometry>
                <mesh filename="package://turtlex_description/meshes/arm/wrist_2_link.new.stl" />
            </geometry>
        </collision>
        <inertial>
            <origin rpy="0 0 0" xyz="0 0 0" />
            <mass value="0.069929" />
            <inertia ixx="0.0000226800" ixy="0.0000000000" ixz="0.0000000000" iyy="0.0000204400" iyz="0.0000008485" izz="0.0000197400" />
        </inertial>
    </link>
    <!-- joints -->
    <joint name="arm_base_joint" type="fixed">
        <origin rpy="0.0 0.0 0.0" xyz="-0.007 0.0 0.0" />
        <parent link="plate_bottom_link" />
        <child link="arm_base_link" />
    </joint>
    <joint name="joint_1" type="revolute">
        <origin rpy="0 0 0" xyz="0 0 0.125" />
        <parent link="arm_base_link" />
        <child link="shoulder_link" />
        <axis xyz="0 0 1" />
        <limit effort="6" lower="-2.617" upper="2.617" velocity="0.785" />
        <dynamics friction="0.1" />
        <!--<limit lower="-2.617" upper="2.617" effort="10000" velocity="0.785" />-->
    </joint>
    <joint name="joint_2" type="revolute">
        <!--origin xyz="0.04825 0 0.14203" rpy="0 0 0" /-->
        <origin rpy="0 0 0" xyz="0 0 0" />
        <parent link="shoulder_link" />
        <child link="biceps_link" />
        <axis xyz="0 1 0" />
        <limit effort="6" lower="-1.571" upper="1.571" velocity="1.571" />
        <dynamics friction="0.1" />
        <!--<limit lower="-1.571" upper="1.571" effort="10000" velocity="1.571" />-->
    </joint>
    <joint name="joint_3" type="revolute">
        <origin rpy="0 1.5707963267948966 0" xyz="0.04825 0 0.14203000000000002" />
        <parent link="biceps_link" />
        <child link="forearm_link" />
        <axis xyz="0 1 0" />
        <limit effort="6" lower="-1.571" upper="1.571" velocity="1.571" />
        <dynamics friction="0.1" />
        <!--<limit lower="-1.571" upper="1.571" effort="10000" velocity="1.571" />-->
    </joint>
    <joint name="joint_4" type="revolute">
        <origin rpy="0 0 0" xyz="0 0 0.14203000000000002" />
        <parent link="forearm_link" />
        <child link="wrist_1_link" />
        <axis xyz="0 1 0" />
        <limit effort="6" lower="-1.745" upper="1.745" velocity="1.571" />
        <dynamics friction="0.1" />
        <!--<limit lower="-1.745" upper="1.745" effort="10000" velocity="1.571" />-->
    </joint>
    <joint name="joint_5" type="revolute">
        <origin rpy="0 0 0" xyz="0 0 0.07150000000000001" />
        <parent link="wrist_1_link" />
        <child link="wrist_2_link" />
        <axis xyz="0 0 1" />
        <limit effort="6" lower="-2.617" upper="2.617" velocity="1.571" />
        <dynamics friction="0.1" />
        <!--<limit lower="-2.617" upper="2.617" effort="10000" velocity="1.571" />-->
    </joint>
    <!-- Gripper -->
    <!--<xacro:include filename="$(find turtlex_description)/urdf/widowx_gripper.xacro"/>-->
    <link name="gripper_rail_link">
        <visual>
            <origin rpy="0 0 1.57" xyz="0 0 0" />
            <geometry>
                <mesh filename="package://turtlex_description/meshes/arm/gripper_rail_link.stl" />
            </geometry>
            <material name="">
                <color rgba="0.15 0.15 0.15 1.0" />
            </material>
        </visual>
        <collision>
            <origin rpy="0 0 1.57" xyz="0 0 0" />
            <geometry>
                <mesh filename="package://turtlex_description/meshes/arm/gripper_rail_link.stl" />
            </geometry>
        </collision>
        <inertial>
            <origin rpy="0 0 0" xyz="0 0 0" />
            <mass value="0.001" />
            <inertia ixx="0.001" ixy="0" ixz="0" iyy="0.001" iyz="0" izz="0.001" />
        </inertial>
    </link>
    <link name="gripper_1_link">
        <visual>
            <origin rpy="0 0 1.57" xyz="0 -0.0007 0" />
            <geometry>
                <mesh filename="package://turtlex_description/meshes/arm/gripper_hand_fixed_link.stl" />
            </geometry>
            <material name="">
                <color rgba="0.15 0.15 0.15 1.0" />
            </material>
        </visual>
        <collision>
            <origin rpy="0 0 1.57" xyz="0 -0.0007 0" />
            <geometry>
                <mesh filename="package://turtlex_description/meshes/arm/gripper_hand_fixed_link.stl" />
            </geometry>
        </collision>
        <inertial>
            <origin rpy="0 0 0" xyz="0 0 0" />
            <mass value="0.016246" />
            <inertia ixx="0.0000047310" ixy="0.0000004560" ixz="0.0000000000" iyy="0.0000015506" iyz="0.0000000000" izz="0.0000037467" />
        </inertial>
    </link>
    <link name="gripper_2_link">
        <visual>
            <origin rpy="0 0 -1.57" xyz="0 0.0007 0" />
            <geometry>
                <mesh filename="package://turtlex_description/meshes/arm/gripper_hand_fixed_link.stl" />
            </geometry>
            <material name="">
                <color rgba="0.15 0.15 0.15 1.0" />
            </material>
        </visual>
        <collision>
            <origin rpy="0 0 -1.57" xyz="0 0.0007 0" />
            <geometry>
                <mesh filename="package://turtlex_description/meshes/arm/gripper_hand_fixed_link.stl" />
            </geometry>
        </collision>
        <inertial>
            <origin rpy="0 0 0" xyz="0 0 0" />
            <mass value="0.016246" />
            <inertia ixx="0.0000047310" ixy="0.0000004560" ixz="0.0000000000" iyy="0.0000015506" iyz="0.0000000000" izz="0.0000037467" />
        </inertial>
    </link>
    <joint name="joint_6" type="fixed">
        <origin rpy="0 0 0" xyz="0 0 0.043000000000000003" />
        <parent link="wrist_2_link" />
        <child link="gripper_rail_link" />
        <axis xyz="0 0 1" />
    </joint>
    <joint name="gripper_prismatic_joint_1" type="prismatic">
        <origin rpy="0 0 0" xyz="0 0 0" />
        <parent link="gripper_rail_link" />
        <child link="gripper_1_link" />
        <axis xyz="0 -1 0" />
        <limit effort="6" lower="0.002" upper="0.031" velocity="0.5" />
        <!-- lower="0" upper="0.027"  ? -->
        <!--<limit lower="0.002" upper="0.031" effort="10000" velocity="0.5" />-->
        <dynamics friction="0.1" />
    </joint>
    <joint name="gripper_prismatic_joint_2" type="prismatic">
        <origin rpy="0 0 0" xyz="0 0 0" />
        <parent link="gripper_rail_link" />
        <child link="gripper_2_link" />
        <!--<mimic joint="gripper_prismatic_joint_1" multiplier="-1" offset="0"/>-->
        <axis xyz="0 1 0" />
        <limit effort="6" lower="0.002" upper="0.031" velocity="0.5" />
        <!-- lower="0" upper="0.027"  ? -->
        <!--<limit lower="0.002" upper="0.031" effort="10000" velocity="0.5" />-->
        <dynamics friction="0.1" />
    </joint>
    <!--<xacro:mimic_joint_plugin_gazebo name_prefix="gripper_prismatic_joint_2"
         parent_joint="gripper_prismatic_joint_1" mimic_joint="gripper_prismatic_joint_2"
         has_pid="true" multiplier="-1.0" max_effort="6" />-->
    <transmission name="trans_wheel_left_joint">
        <type>transmission_interface/SimpleTransmission</type>
        <joint name="wheel_left_joint">
            <hardwareInterface>hardware_interface/EffortJointInterface</hardwareInterface>
        </joint>
        <actuator name="wheel_left_joint_motor">
            <hardwareInterface>hardware_interface/EffortJointInterface</hardwareInterface>
            <mechanicalReduction>1</mechanicalReduction>
        </actuator>
    </transmission>
    <transmission name="trans_wheel_right_joint">
        <type>transmission_interface/SimpleTransmission</type>
        <joint name="wheel_right_joint">
            <hardwareInterface>hardware_interface/EffortJointInterface</hardwareInterface>
        </joint>
        <actuator name="wheel_right_joint_motor">
            <hardwareInterface>hardware_interface/EffortJointInterface</hardwareInterface>
            <mechanicalReduction>1</mechanicalReduction>
        </actuator>
    </transmission>
    <transmission name="trans_joint_1">
        <type>transmission_interface/SimpleTransmission</type>
        <joint name="joint_1">
            <hardwareInterface>hardware_interface/EffortJointInterface</hardwareInterface>
        </joint>
        <actuator name="joint_1_motor">
            <hardwareInterface>hardware_interface/EffortJointInterface</hardwareInterface>
            <mechanicalReduction>1</mechanicalReduction>
        </actuator>
    </transmission>
    <transmission name="trans_joint_2">
        <type>transmission_interface/SimpleTransmission</type>
        <joint name="joint_2">
            <hardwareInterface>hardware_interface/EffortJointInterface</hardwareInterface>
        </joint>
        <actuator name="joint_2_motor">
            <hardwareInterface>hardware_interface/EffortJointInterface</hardwareInterface>
            <mechanicalReduction>1</mechanicalReduction>
        </actuator>
    </transmission>
    <transmission name="trans_joint_3">
        <type>transmission_interface/SimpleTransmission</type>
        <joint name="joint_3">
            <hardwareInterface>hardware_interface/EffortJointInterface</hardwareInterface>
        </joint>
        <actuator name="joint_3_motor">
            <hardwareInterface>hardware_interface/EffortJointInterface</hardwareInterface>
            <mechanicalReduction>1</mechanicalReduction>
        </actuator>
    </transmission>
    <transmission name="trans_joint_4">
        <type>transmission_interface/SimpleTransmission</type>
        <joint name="joint_4">
            <hardwareInterface>hardware_interface/EffortJointInterface</hardwareInterface>
        </joint>
        <actuator name="joint_4_motor">
            <hardwareInterface>hardware_interface/EffortJointInterface</hardwareInterface>
            <mechanicalReduction>1</mechanicalReduction>
        </actuator>
    </transmission>
    <transmission name="trans_joint_5">
        <type>transmission_interface/SimpleTransmission</type>
        <joint name="joint_5">
            <hardwareInterface>hardware_interface/EffortJointInterface</hardwareInterface>
        </joint>
        <actuator name="joint_5_motor">
            <hardwareInterface>hardware_interface/EffortJointInterface</hardwareInterface>
            <mechanicalReduction>1</mechanicalReduction>
        </actuator>
    </transmission>
    <transmission name="trans_gripper_prismatic_joint_1">
        <type>transmission_interface/SimpleTransmission</type>
        <joint name="gripper_prismatic_joint_1">
            <hardwareInterface>hardware_interface/EffortJointInterface</hardwareInterface>
        </joint>
        <actuator name="gripper_prismatic_joint_1_motor">
            <hardwareInterface>hardware_interface/EffortJointInterface</hardwareInterface>
            <mechanicalReduction>1</mechanicalReduction>
        </actuator>
    </transmission>
    <transmission name="trans_gripper_prismatic_joint_2">
        <type>transmission_interface/SimpleTransmission</type>
        <joint name="gripper_prismatic_joint_2">
            <hardwareInterface>hardware_interface/EffortJointInterface</hardwareInterface>
        </joint>
        <actuator name="gripper_prismatic_joint_2_motor">
            <hardwareInterface>hardware_interface/EffortJointInterface</hardwareInterface>
            <mechanicalReduction>1</mechanicalReduction>
        </actuator>
    </transmission>
    <gazebo>
        <plugin name="gazebo_ros_control" filename="libgazebo_ros_control.so">
            <robotNamespace>/</robotNamespace>
        </plugin>
    </gazebo>
</robot>